<mujoco model="pick_place">
  <compiler angle="radian" meshdir="/home/dwijen/miniforge3/envs/vipgeai/lib/python3.10/site-packages/robohive/simhive/franka_sim/" texturedir="/home/dwijen/miniforge3/envs/vipgeai/lib/python3.10/site-packages/robohive/simhive/franka_sim/"/>
  <size njmax="1000" nconmax="1000" nuser_geom="1" nuser_actuator="5"/>
  <visual>
    <map force="0.1" fogstart="1.5" fogend="5" shadowclip="2"/>
  </visual>
  <statistic extent="3.5"/>
  <default class="main">
    <default class="scene">
      <geom contype="0" conaffinity="0"/>
    </default>
    <default class="viz_simpleWoodTable">
      <geom material="M_simpleWoodTable"/>
    </default>
    <default class="viz_simpleMarbleTable">
      <geom type="mesh" contype="0" conaffinity="0" group="1" material="M_simpleMarbleTable"/>
    </default>
    <default class="viz_simpleGraniteTable">
      <geom material="M_simpleGraniteTable"/>
    </default>
    <default class="body_simpleTable">
      <geom group="4" rgba="0.4 0.5 0.6 1"/>
    </default>
    <default class="vention">
      <geom contype="0" conaffinity="0" group="1"/>
      <default class="vention_collision">
        <geom conaffinity="1" group="4" margin="0.001" rgba="0.4 0.5 0.6 1"/>
      </default>
    </default>
    <default class="panda">
      <joint limited="true"/>
      <general ctrllimited="true" forcelimited="true" biastype="affine" biasprm="0 -1" user="1002 40 2001 -0.005 0.005"/>
      <default class="panda_viz">
        <geom type="mesh" contype="0" conaffinity="0" rgba="0.92 0.92 0.95 1"/>
        <general user="1002 40 2001 -0.005 0.005"/>
      </default>
      <default class="panda_grey_viz">
        <geom type="mesh" contype="0" conaffinity="0" rgba="0.4 0.4 0.4 1"/>
        <general user="1002 40 2001 -0.005 0.005"/>
      </default>
      <default class="panda_col">
        <geom type="mesh" group="3" rgba="0.5 0.6 0.7 1"/>
        <general user="1002 40 2001 -0.005 0.005"/>
      </default>
      <default class="panda_arm">
        <joint damping="100"/>
        <general user="1002 40 2001 -0.005 0.005"/>
      </default>
      <default class="panda_forearm">
        <joint damping="10"/>
        <general user="1002 40 2001 -0.005 0.005"/>
      </default>
      <default class="panda_finger">
        <joint armature="5" damping="100"/>
        <geom conaffinity="0" condim="6" group="3" friction="1 0.5" solref="0.01" solimp="0.8 0.9" margin="0.001" rgba="0.5 0.6 0.7 0.4"/>
        <general user="1002 40 2001 -0.0001 0.0001"/>
      </default>
    </default>
    <default class="panda_overlay"/>
    <default class="viz_stl_Metal_bin">
      <geom type="mesh" group="1" material="M_Metal_bin"/>
    </default>
  </default>
  <asset>
    <texture type="skybox" name="skybox" file="../scene_sim/textures/dawn.png" gridsize="3 4" gridlayout=".U..LFRB.D.."/>
    <texture type="2d" name="texplane" file="../scene_sim/textures/white_marble_tile2.png"/>
    <texture type="2d" name="texwindow" file="../scene_sim/textures/windows0.png"/>
    <texture type="cube" name="T_simpleWoodTable" file="../furniture_sim/common/textures/wood1.png"/>
    <texture type="cube" name="T_simpleMarbleTable" file="../furniture_sim/common/textures/stone0.png"/>
    <texture type="cube" name="T_simpleGraniteTable" file="../furniture_sim/common/textures/stone1.png"/>
    <texture type="cube" name="T_Metal_bin" file="../furniture_sim/common/textures/metal0.png"/>
    <material name="MatPlane" texture="texplane" texuniform="true" texrepeat="4 4" reflectance="0.01"/>
    <material name="MatMetal" emission="0.01" specular="0.2" rgba="0.31 0.3 0.3 1"/>
    <material name="MatGlass" emission="0.25" specular="0.4" reflectance="1" rgba="0.6 0.6 0.65 0.1"/>
    <material name="MatWindow" texture="texwindow" texuniform="true" rgba="1 0 0 1"/>
    <material name="M_simpleWoodTable" texture="T_simpleWoodTable" shininess="0.2" reflectance="0.3" rgba="0.8 0.8 0.8 1"/>
    <material name="M_simpleMarbleTable" texture="T_simpleMarbleTable" shininess="1" reflectance="1" rgba="0.75 0.75 0.75 1"/>
    <material name="M_simpleGraniteTable" texture="T_simpleGraniteTable" shininess="1" reflectance="1" rgba="0.75 0.75 0.75 1"/>
    <material name="vention_black" reflectance="1" rgba="0.05 0.05 0.1 1"/>
    <material name="vention_blue" shininess="0.1" reflectance="10" rgba="0.14 0.3 0.52 1"/>
    <material name="M_Metal_bin" texture="T_Metal_bin" texrepeat="3 3" reflectance="0.7"/>
    <mesh name="wall" file="../scene_sim/meshes/highwindow.stl"/>
    <mesh name="skyline" file="../scene_sim/meshes/skyline.stl" scale="2.2 2.2 1"/>
    <mesh name="robohive" file="../scene_sim/meshes/robohive_text.stl"/>
    <mesh name="robohive_half" file="../scene_sim/meshes/robohive_logohalf.stl" scale="4 4 4"/>
    <mesh name="link0_col" file="../franka_sim/meshes/collision/link0.stl"/>
    <mesh name="link1_col" file="../franka_sim/meshes/collision/link1.stl"/>
    <mesh name="link2_col" file="../franka_sim/meshes/collision/link2.stl"/>
    <mesh name="link3_col" file="../franka_sim/meshes/collision/link3.stl"/>
    <mesh name="link4_col" file="../franka_sim/meshes/collision/link4.stl"/>
    <mesh name="link5_col" file="../franka_sim/meshes/collision/link5.stl"/>
    <mesh name="link6_col" file="../franka_sim/meshes/collision/link6.stl"/>
    <mesh name="link7_col" file="../franka_sim/meshes/collision/link7.stl"/>
    <mesh name="hand_col" file="../franka_sim/meshes/collision/hand.stl"/>
    <mesh name="link0_viz" file="../franka_sim/meshes/visual/link0.stl"/>
    <mesh name="link1_viz" file="../franka_sim/meshes/visual/link1.stl"/>
    <mesh name="link2_viz" file="../franka_sim/meshes/visual/link2.stl"/>
    <mesh name="link3_viz" file="../franka_sim/meshes/visual/link3.stl"/>
    <mesh name="link3_dark_viz" file="../franka_sim/meshes/visual/link3_dark.stl" scale="1.01 1.01 1.01"/>
    <mesh name="link4_viz" file="../franka_sim/meshes/visual/link4.stl"/>
    <mesh name="link4_dark_viz" file="../franka_sim/meshes/visual/link4_dark.stl" scale="1.01 1.01 1.01"/>
    <mesh name="link5_viz" file="../franka_sim/meshes/visual/link5.stl"/>
    <mesh name="link5_dark_viz" file="../franka_sim/meshes/visual/link5_dark.stl" scale="1.01 1.01 1.01"/>
    <mesh name="link6_viz" file="../franka_sim/meshes/visual/link6.stl"/>
    <mesh name="link6_dark_viz" file="../franka_sim/meshes/visual/link6_dark.stl" scale="1.01 1.01 1.01"/>
    <mesh name="link7_viz" file="../franka_sim/meshes/visual/link7.stl"/>
    <mesh name="link7_dark_viz" file="../franka_sim/meshes/visual/link7_dark.stl" scale="1.01 1.01 1.01"/>
    <mesh name="hand_viz" file="../franka_sim/meshes/visual/hand.stl"/>
    <mesh name="finger_col" file="../franka_sim/meshes/collision/finger.stl" scale="1.75 1 1.75"/>
    <mesh name="finger_viz" file="../franka_sim/meshes/collision/finger.stl" scale="1.75 1 1.75"/>
    <mesh name="bin" file="../furniture_sim/bin/meshes/bin.stl" scale="0.01 0.01 0.01"/>
    <mesh name="busbin" file="../furniture_sim/bin/meshes/busbin.stl"/>
  </asset>
  <worldbody>
    <geom name="skyline" class="scene" pos="0 0 -3" type="mesh" material="MatWindow" rgba="0.3 0.3 0.27 1" mesh="skyline"/>
    <geom name="floor" class="scene" size="12 12 0.1" pos="0 0 0.0001" type="plane" contype="1" conaffinity="1" material="MatPlane"/>
    <geom name="roof" class="scene" size="12 12 0.2" pos="0 0 8" quat="0.000796327 1 0 0" type="plane" material="MatMetal"/>
    <geom name="robohive" pos="0 -0.45 0" type="mesh" contype="0" conaffinity="0" rgba="0.3 0.3 0.3 1" mesh="robohive"/>
    <geom pos="0 0 -0.03" type="mesh" contype="0" conaffinity="0" rgba="1 0.6 0 2" mesh="robohive_half"/>
    <geom pos="0 0 -0.03" quat="0.000796327 0 0 1" type="mesh" contype="0" conaffinity="0" rgba="0.3 0.3 0.3 1" mesh="robohive_half"/>
    <geom class="scene" pos="0 10 0" type="mesh" material="MatMetal" mesh="wall"/>
    <geom class="scene" size="5 0.01 3.5" pos="0 10 3.5" type="box" material="MatGlass"/>
    <geom class="scene" pos="0 -10 0" quat="0.000796327 0 0 -1" type="mesh" material="MatMetal" mesh="wall"/>
    <geom class="scene" size="5 0.01 3.5" pos="0 -10 3.5" type="box" material="MatGlass"/>
    <geom class="scene" pos="10 0 0" quat="0.707388 0 0 -0.706825" type="mesh" material="MatMetal" mesh="wall"/>
    <geom class="scene" size="0.01 5 3.5" pos="10 0 3.5" type="box" material="MatGlass"/>
    <geom class="scene" pos="-10 0 0" quat="0.707388 0 0 0.706825" type="mesh" material="MatMetal" mesh="wall"/>
    <geom class="scene" size="0.01 5 3.5" pos="-10 0 3.5" type="box" material="MatGlass"/>
    <site name="xaxis" pos="0.5 0 0" quat="0.707107 0 -0.707107 0" size="0.005 0.5" group="3" type="capsule" rgba="1 0 0 0.25"/>
    <site name="yaxis" pos="0 0.5 0" quat="0.707107 0.707107 0 0" size="0.005 0.5" group="3" type="capsule" rgba="0 1 0 0.25"/>
    <site name="workspace" pos="0 0.475 1" size="0.6 0.375 0.25" group="3" type="box" rgba="0 0 0.4 0.2"/>
    <site name="pick_target" pos="0 0.5 1.25" size="0.088" group="1" rgba="0.1 0.8 0.2 0.4"/>
    <site name="drop_target" pos="0.183666 0.324637 0.85" quat="9.51179e-05 0.119446 0.99284 -0.000790626" size="0.088 0.021" group="1" type="cylinder" rgba="0.1 0.8 0.2 0.4"/>
    <camera name="left_cam" pos="-1.2 -0.5 1.8" quat="0.780273 0.490172 -0.220077 -0.320112"/>
    <camera name="right_cam" pos="1.2 -0.5 1.8" quat="0.762214 0.501456 0.210612 0.351019"/>
    <camera name="top_cam" pos="0 0.5 2.2"/>
    <light name="left_light" pos="-4 -4 7" dir="0.57735 0.57735 -0.57735" diffuse="0.4 0.35 0.3" specular="0.4 0.35 0.3"/>
    <light name="right_light" pos="4 -4 7" dir="-0.57735 0.57735 -0.57735" diffuse="0.4 0.35 0.3" specular="0.4 0.35 0.3"/>
    <light name="front_light" pos="0 4 7" dir="0 -0.707107 -0.707107" diffuse="0.4 0.35 0.3" specular="0.4 0.35 0.3"/>
    <body pos="0 0 0.823" quat="0.707388 0 0 0.706825">
      <body name="panda0_link0" childclass="panda">
        <geom class="panda_viz" mesh="link0_viz"/>
        <geom class="panda_col" mass="2.91242" mesh="link0_col"/>
        <body name="panda0_link1" pos="0 0 0.333">
          <joint name="panda0_joint1" class="panda_arm" pos="0 0 0" axis="0 0 1" range="-2.8973 2.8973"/>
          <geom class="panda_viz" mesh="link1_viz"/>
          <geom class="panda_col" mass="2.7063" mesh="link1_col"/>
          <body name="panda0_link2" quat="0.707107 -0.707107 0 0">
            <joint name="panda0_joint2" class="panda_arm" pos="0 0 0" axis="0 0 1" range="-1.7628 1.7628"/>
            <geom class="panda_viz" mesh="link2_viz"/>
            <geom class="panda_col" mass="2.73046" mesh="link2_col"/>
            <body name="panda0_link3" pos="0 -0.316 0" quat="0.707107 0.707107 0 0">
              <joint name="panda0_joint3" class="panda_arm" pos="0 0 0" axis="0 0 1" range="-2.8973 2.8973"/>
              <geom class="panda_viz" mesh="link3_viz"/>
              <geom class="panda_grey_viz" pos="0 0.001 0" mesh="link3_dark_viz"/>
              <geom class="panda_col" mass="2.04104" mesh="link3_col"/>
              <body name="panda0_link4" pos="0.0825 0 0" quat="0.707107 0.707107 0 0">
                <joint name="panda0_joint4" class="panda_arm" pos="0 0 0" axis="0 0 1" range="-3.0718 -0.4"/>
                <geom class="panda_viz" mesh="link4_viz"/>
                <geom class="panda_grey_viz" mesh="link4_dark_viz"/>
                <geom class="panda_col" mass="2.08129" mesh="link4_col"/>
                <body name="panda0_link5" pos="-0.0825 0.384 0" quat="0.707107 -0.707107 0 0">
                  <joint name="panda0_joint5" class="panda_forearm" pos="0 0 0" axis="0 0 1" range="-2.8973 2.8973"/>
                  <geom class="panda_viz" mesh="link5_viz"/>
                  <geom class="panda_grey_viz" mesh="link5_dark_viz"/>
                  <geom class="panda_col" mass="3.00049" mesh="link5_col"/>
                  <body name="panda0_link6" quat="0.500398 0.5 -0.499602 0.5">
                    <joint name="panda0_joint6" class="panda_forearm" pos="0 0 0" axis="0 0 1" range="-1.6573 2.1127"/>
                    <geom class="panda_viz" mesh="link6_viz"/>
                    <geom class="panda_grey_viz" mesh="link6_dark_viz"/>
                    <geom class="panda_col" mass="1.3235" mesh="link6_col"/>
                    <body name="panda0_link7" pos="0.088 0 0" quat="0.653541 0.653021 -0.270491 0.270706">
                      <joint name="panda0_joint7" class="panda_forearm" pos="0 0 0" axis="0 0 1" range="-2.8973 2.8973"/>
                      <geom class="panda_viz" rgba="0.8 0.8 0.82 1" mesh="link7_viz"/>
                      <geom class="panda_grey_viz" pos="0 0 -0.0008" mesh="link7_dark_viz"/>
                      <geom class="panda_col" mass="0.2" mesh="link7_col"/>
                      <site name="end_effector" pos="0 0 0.21" quat="0.92388 0 0 -0.382683" size="0.01"/>
                      <camera name="Franka_wrist_cam" pos="0.05 -0.05 0.15" quat="0.126001 0.911084 0.388578 0.0552895"/>
                      <body name="panda0_gripper">
                        <geom class="panda_viz" pos="0 0 0.107" quat="0.92388 0 0 -0.382683" mesh="hand_viz"/>
                        <geom class="panda_col" pos="0 0 0.107" quat="0.92388 0 0 -0.382683" mass="0.81909" mesh="hand_col"/>
                        <body name="panda0_leftfinger" childclass="panda_finger" pos="0 0 0.1654" quat="0.92388 0 0 -0.382683">
                          <inertial pos="-1.57863e-05 0.0118731 0.0434103" quat="0.705868 0.0310348 -0.0314925 0.706962" mass="0.0927059" diaginertia="6.57134e-05 6.09611e-05 1.09932e-05"/>
                          <joint name="panda0_finger_joint1" class="panda_finger" pos="0 0 0" axis="0 1 0" type="slide" range="0 0.04"/>
                          <geom class="panda_viz" mesh="finger_viz"/>
                          <geom size="0.007 0.00912414" pos="0 0.0075 0.0875" quat="0.707107 0.116248 0.697486 0" type="capsule"/>
                          <geom size="0.007 0.00912414" pos="0 0.0075 0.0875" quat="0.707107 -0.116248 0.697486 0" type="capsule"/>
                          <geom size="0.0075 0.00912414" pos="0 0.0085 0.0775" quat="0.707107 0.116248 0.697486 0" type="capsule"/>
                          <geom size="0.0075 0.00912414" pos="0 0.0085 0.0775" quat="0.707107 -0.116248 0.697486 0" type="capsule"/>
                          <geom size="0.0082 0.00912414" pos="0 0.0095 0.0675" quat="0.707107 0.116248 0.697486 0" type="capsule"/>
                          <geom size="0.0082 0.00912414" pos="0 0.0095 0.0675" quat="0.707107 -0.116248 0.697486 0" type="capsule"/>
                          <geom size="0.009 0.00912414" pos="0 0.0105 0.0575" quat="0.707107 0.116248 0.697486 0" type="capsule"/>
                          <geom size="0.009 0.00912414" pos="0 0.0105 0.0575" quat="0.707107 -0.116248 0.697486 0" type="capsule"/>
                          <geom size="0.01 0.00912414" pos="0 0.012 0.0475" quat="0.707107 0.116248 0.697486 0" type="capsule"/>
                          <geom size="0.01 0.00912414" pos="0 0.012 0.0475" quat="0.707107 -0.116248 0.697486 0" type="capsule"/>
                          <geom size="0.011 0.00912414" pos="0 0.0135 0.035" quat="0.707107 0.116248 0.697486 0" type="capsule"/>
                          <geom size="0.011 0.00912414" pos="0 0.0135 0.035" quat="0.707107 -0.116248 0.697486 0" type="capsule"/>
                          <geom size="0.0185 0.012 0.0175" pos="0 0.014 0.015" quat="0.999888 0.0149994 0 0" type="box"/>
                        </body>
                        <body name="panda0_rightfinger" childclass="panda_finger" pos="0 0 0.1654" quat="0.92388 0 0 -0.382683">
                          <inertial pos="1.57863e-05 -0.0118731 0.0434103" quat="0.705868 -0.0310348 0.0314925 0.706962" mass="0.0927059" diaginertia="6.57134e-05 6.09611e-05 1.09932e-05"/>
                          <joint name="panda0_finger_joint2" class="panda_finger" pos="0 0 0" axis="0 -1 0" type="slide" range="0 0.04"/>
                          <geom class="panda_viz" quat="0 0 0 1" mesh="finger_viz"/>
                          <geom size="0.007 0.00912414" pos="0 -0.0075 0.0875" quat="0.707107 -0.116248 0.697486 0" type="capsule"/>
                          <geom size="0.007 0.00912414" pos="0 -0.0075 0.0875" quat="0.707107 0.116248 0.697486 0" type="capsule"/>
                          <geom size="0.0075 0.00912414" pos="0 -0.0085 0.0775" quat="0.707107 -0.116248 0.697486 0" type="capsule"/>
                          <geom size="0.0075 0.00912414" pos="0 -0.0085 0.0775" quat="0.707107 0.116248 0.697486 0" type="capsule"/>
                          <geom size="0.0082 0.00912414" pos="0 -0.0095 0.0675" quat="0.707107 -0.116248 0.697486 0" type="capsule"/>
                          <geom size="0.0082 0.00912414" pos="0 -0.0095 0.0675" quat="0.707107 0.116248 0.697486 0" type="capsule"/>
                          <geom size="0.009 0.00912414" pos="0 -0.0105 0.0575" quat="0.707107 -0.116248 0.697486 0" type="capsule"/>
                          <geom size="0.009 0.00912414" pos="0 -0.0105 0.0575" quat="0.707107 0.116248 0.697486 0" type="capsule"/>
                          <geom size="0.01 0.00912414" pos="0 -0.012 0.0475" quat="0.707107 -0.116248 0.697486 0" type="capsule"/>
                          <geom size="0.01 0.00912414" pos="0 -0.012 0.0475" quat="0.707107 0.116248 0.697486 0" type="capsule"/>
                          <geom size="0.011 0.00912414" pos="0 -0.0135 0.035" quat="0.707107 -0.116248 0.697486 0" type="capsule"/>
                          <geom size="0.011 0.00912414" pos="0 -0.0135 0.035" quat="0.707107 0.116248 0.697486 0" type="capsule"/>
                          <geom size="0.0185 0.012 0.0175" pos="0 -0.014 0.015" quat="0.999888 -0.0149994 0 0" type="box"/>
                        </body>
                      </body>
                    </body>
                  </body>
                </body>
              </body>
            </body>
          </body>
        </body>
      </body>
    </body>
    <body name="ventiontable" pos="0 -0.3 0">
      <body name="vention table" childclass="vention">
        <geom size="0.04 0.01" pos="-0.585 -0.383 0.01" type="cylinder" material="vention_black"/>
        <geom size="0.04 0.01" pos="0.585 -0.383 0.01" type="cylinder" material="vention_black"/>
        <geom size="0.04 0.01" pos="-0.585 0.383 0.01" type="cylinder" material="vention_black"/>
        <geom size="0.04 0.01" pos="0.585 0.383 0.01" type="cylinder" material="vention_black"/>
        <geom size="0.01 0.02" pos="-0.585 -0.383 0.03" type="cylinder"/>
        <geom size="0.01 0.02" pos="0.585 -0.383 0.03" type="cylinder"/>
        <geom size="0.01 0.02" pos="-0.585 0.383 0.03" type="cylinder"/>
        <geom size="0.01 0.02" pos="0.585 0.383 0.03" type="cylinder"/>
        <geom size="0.023 0.023 0.387" pos="-0.585 -0.383 0.435" type="box" material="vention_blue"/>
        <geom size="0.023 0.023 0.387" pos="0.585 -0.383 0.435" type="box" material="vention_blue"/>
        <geom size="0.023 0.023 0.387" pos="-0.585 0.383 0.435" type="box" material="vention_blue"/>
        <geom size="0.023 0.023 0.387" pos="0.585 0.383 0.435" type="box" material="vention_blue"/>
        <geom size="0.023 0.023 0.337" pos="0 0.377 0.44" type="box" material="vention_blue"/>
        <geom size="0.023 0.023 0.337" pos="0 -0.377 0.44" type="box" material="vention_blue"/>
        <geom size="0.612 0.409 0.023" pos="0 0 0.801" type="box" material="vention_black"/>
        <geom size="0.614 0.411 0.023" pos="0 0 0.79" type="box" material="vention_blue"/>
        <geom size="0.602 0.399 0.005" pos="0 0 0.15" type="box" material="vention_black"/>
        <geom size="0.604 0.401 0.023" pos="0 0 0.124" type="box" material="vention_blue"/>
        <geom class="vention_collision" size="0.604 0.401 0.411" pos="0 0 0.413" type="box"/>
      </body>
    </body>
    <body name="scenetable" pos="0 0.49 0.065">
      <body name="simpleMarbleTable" childclass="body_simpleTable">
        <geom class="viz_simpleMarbleTable" size="0.7 0.375 0.025" pos="0 0 0.735" type="box"/>
        <geom class="viz_simpleMarbleTable" size="0.59 0.26 0.05" pos="0 0 0.66" type="box" rgba="0.2 0.1 0.1 1"/>
        <geom class="viz_simpleMarbleTable" size="0.025 0.025 0.305" pos="-0.565 0.235 0.305" type="box" rgba="0.2 0.1 0.1 1"/>
        <geom class="viz_simpleMarbleTable" size="0.025 0.025 0.305" pos="-0.565 -0.235 0.305" type="box" rgba="0.2 0.1 0.1 1"/>
        <geom class="viz_simpleMarbleTable" size="0.025 0.025 0.305" pos="0.565 0.235 0.305" type="box" rgba="0.2 0.1 0.1 1"/>
        <geom class="viz_simpleMarbleTable" size="0.025 0.025 0.305" pos="0.565 -0.235 0.305" type="box" rgba="0.2 0.1 0.1 1"/>
        <geom size="0.6 0.375 0.025" pos="0 0 0.735" type="box" mass="40"/>
        <geom size="0.59 0.26 0.05" pos="0 0 0.66" type="box"/>
        <geom size="0.025 0.025 0.305" pos="-0.565 0.235 0.305" type="box"/>
        <geom size="0.025 0.025 0.305" pos="-0.565 -0.235 0.305" type="box"/>
        <geom size="0.025 0.025 0.305" pos="0.565 0.235 0.305" type="box"/>
        <geom size="0.025 0.025 0.305" pos="0.565 -0.235 0.305" type="box"/>
      </body>
    </body>
    <body name="busbin1" pos="0.235 0.5 0.825">
      <geom class="viz_stl_Metal_bin" quat="0.000796327 0 0 1" contype="0" conaffinity="0" mesh="busbin"/>
      <geom size="0.012 0.33 0.09" pos="-0.21 0 0.09" quat="0.998488 0 -0.0549723 0" type="box" group="3"/>
      <geom size="0.012 0.33 0.09" pos="0.21 0 0.09" quat="0.998488 0 0.0549723 0" type="box" group="3"/>
      <geom size="0.012 0.24 0.09" pos="0 -0.3 0.09" quat="0.706319 0.0388867 -0.0388558 0.705756" type="box" group="3"/>
      <geom size="0.012 0.24 0.09" pos="0 0.3 0.09" quat="0.706319 -0.0388867 0.0388558 0.705756" type="box" group="3"/>
      <geom size="0.21 0.3 0.012" pos="0 0 0.012" type="box" group="3"/>
    </body>
    <body name="busbin2" pos="-0.235 0.5 0.825">
      <geom class="viz_stl_Metal_bin" quat="0.000796327 0 0 1" contype="0" conaffinity="0" mesh="busbin"/>
      <geom size="0.012 0.33 0.09" pos="-0.21 0 0.09" quat="0.998488 0 -0.0549723 0" type="box" group="3"/>
      <geom size="0.012 0.33 0.09" pos="0.21 0 0.09" quat="0.998488 0 0.0549723 0" type="box" group="3"/>
      <geom size="0.012 0.24 0.09" pos="0 -0.3 0.09" quat="0.706319 0.0388867 -0.0388558 0.705756" type="box" group="3"/>
      <geom size="0.012 0.24 0.09" pos="0 0.3 0.09" quat="0.706319 -0.0388867 0.0388558 0.705756" type="box" group="3"/>
      <geom size="0.21 0.3 0.012" pos="0 0 0.012" type="box" group="3"/>
    </body>
    <body name="box" pos="-0.23 0.675 0.9">
      <inertial pos="0 0 0" mass="0.076" diaginertia="0.0001 0.0001 0.0001"/>
      <joint name="box_freejoint" type="free" limited="false" actuatorfrclimited="false"/>
      <geom size="0.05 0.02 0.06" type="box" group="1" mass="0" rgba="0.33 0.52 0.73 1"/>
      <site name="box" pos="0 0 0" size="0.01"/>
    </body>
  </worldbody>
  <actuator>
    <general name="panda0_joint1" class="panda" joint="panda0_joint1" ctrlrange="-2.9671 2.9671" forcerange="-87 87" gainprm="870" biasprm="0 -870"/>
    <general name="panda0_joint2" class="panda" joint="panda0_joint2" ctrlrange="-1.8326 1.8326" forcerange="-87 87" gainprm="870" biasprm="0 -870"/>
    <general name="panda0_joint3" class="panda" joint="panda0_joint3" ctrlrange="-2.9671 2.9671" forcerange="-87 87" gainprm="870" biasprm="0 -870"/>
    <general name="panda0_joint4" class="panda" joint="panda0_joint4" ctrlrange="-3.1416 0" forcerange="-87 87" gainprm="870" biasprm="0 -870"/>
    <general name="panda0_joint5" class="panda" joint="panda0_joint5" ctrlrange="-2.9671 2.9671" forcerange="-12 12" gainprm="120" biasprm="0 -120"/>
    <general name="panda0_joint6" class="panda" joint="panda0_joint6" ctrlrange="-1.66 2.1817" forcerange="-12 12" gainprm="120" biasprm="0 -120"/>
    <general name="panda0_joint7" class="panda" joint="panda0_joint7" ctrlrange="-2.9671 2.9671" forcerange="-12 12" gainprm="120" biasprm="0 -120"/>
    <general name="r_gripper_finger_joint" class="panda_finger" joint="panda0_finger_joint1" ctrlrange="0 0.04" forcerange="-70 70" gainprm="500" biasprm="0 -500"/>
    <general name="l_gripper_finger_joint" class="panda_finger" joint="panda0_finger_joint2" ctrlrange="0 0.04" forcerange="-70 70" gainprm="500" biasprm="0 -500"/>
  </actuator>
  <sensor>
    <jointpos joint="panda0_joint1" name="fr_arm_jp1"/>
    <jointpos joint="panda0_joint2" name="fr_arm_jp2"/>
    <jointpos joint="panda0_joint3" name="fr_arm_jp3"/>
    <jointpos joint="panda0_joint4" name="fr_arm_jp4"/>
    <jointpos joint="panda0_joint5" name="fr_arm_jp5"/>
    <jointpos joint="panda0_joint6" name="fr_arm_jp6"/>
    <jointpos joint="panda0_joint7" name="fr_arm_jp7"/>
    <jointvel joint="panda0_joint1" name="fr_arm_jv1"/>
    <jointvel joint="panda0_joint2" name="fr_arm_jv2"/>
    <jointvel joint="panda0_joint3" name="fr_arm_jv3"/>
    <jointvel joint="panda0_joint4" name="fr_arm_jv4"/>
    <jointvel joint="panda0_joint5" name="fr_arm_jv5"/>
    <jointvel joint="panda0_joint6" name="fr_arm_jv6"/>
    <jointvel joint="panda0_joint7" name="fr_arm_jv7"/>
    <jointpos joint="panda0_finger_joint1" name="fr_fin_jp1"/>
    <jointpos joint="panda0_finger_joint2" name="fr_fin_jp2"/>
    <jointvel joint="panda0_finger_joint1" name="fr_fin_jv1"/>
    <jointvel joint="panda0_finger_joint2" name="fr_fin_jv2"/>
  </sensor>
</mujoco>
